<?xml version="1.0"?>
 <robot name="ppprobot">
 <material name="red">
 <color rgba="1 0 0 0.5" />
 </material>
 <material name="green">
 <color rgba="0 1 0 0.5" />
 </material>
 <material name="ilayda">
 <color rgba="0.5 0.5 0 0.5" />
 </material>
 <material name="blue">
 <color rgba="0 0 1 0.5" />
 </material>
<link name="base_link">
 <visual>
 <geometry>
 <box size="1 1 0.1" />
 </geometry>
 <origin xyz="0 0 0" />
 <material name="blue" />
 </visual>
 </link> 
 <link name="link1">
 <visual>
 <geometry>
 <mesh filename="package://sekil1.stl"/>
 </geometry>
 <material name="ilayda" />
 </visual>
 </link>
 <link name="link2">
 <visual>
 <geometry>
 <mesh filename="package://sekil2.stl"/>
 </geometry>
 <origin xyz="0 0 0.1" />
 <material name="green" />
 </visual>
 </link>
<link name="end">
 <visual>
 <geometry>
 <mesh filename="package://sekil3.stl"/>
 </geometry>
 <origin xyz="0 0.05 0.5" />
 <material name="red" />
 </visual>
 </link>
<joint name="q1" type="prismatic">
 <parent link="base_link" />
 <child link="link1" />
 <limit velocity="170" effort="200" lower="-1" upper="0.93" />
 <origin xyz="0 0 0.1" />
 <axis xyz="1 0 0"/>
 </joint>
 <joint name="q2" type="prismatic">
 <parent link="link1" />
 <child link="link2" />
 <limit velocity="170" effort="200" lower="-1" upper="0.93" />
 <origin xyz="0 -0.1 0.2" />
 <axis xyz="0 0 1" />
 </joint>
 <joint name="q3" type="prismatic">
 <parent link="link2" />
 <child link="end" />
 <limit velocity="170" effort="200" lower="-1" upper="0.93" />
 <origin xyz="0 0 0" />
 <axis xyz="0 0 1" />
 </joint>
 </robot>